<?xml version="1.0" ?>
<!-- =================================================================================== -->
<!-- |    This document was autogenerated by xacro from /home/mbs/mbs_dev/mbs_ws/workspaces/mbs_husky_atc/src/mbs/mbs_husky_description/urdf/include/husky.urdf.xacro | -->
<!-- |    EDITING THIS FILE BY HAND IS NOT RECOMMENDED                                 | -->
<!-- =================================================================================== -->
<!--
Software License Agreement (BSD)

\file      husky.urdf.xacro
\authors   Paul Bovbel <pbovbel@clearpathrobotics.com>, Devon Ash <dash@clearpathrobotics.com>
\copyright Copyright (c) 2015, Clearpath Robotics, Inc., All rights reserved.

Redistribution and use in source and binary forms, with or without modification, are permitted provided that
the following conditions are met:
 * Redistributions of source code must retain the above copyright notice, this list of conditions and the
   following disclaimer.
 * Redistributions in binary form must reproduce the above copyright notice, this list of conditions and the
   following disclaimer in the documentation and/or other materials provided with the distribution.
 * Neither the name of Clearpath Robotics nor the names of its contributors may be used to endorse or promote
   products derived from this software without specific prior written permission.

THIS SOFTWARE IS PROVIDED BY THE COPYRIGHT HOLDERS AND CONTRIBUTORS "AS IS" AND ANY EXPRESS OR IMPLIED WAR-
RANTIES, INCLUDING, BUT NOT LIMITED TO, THE IMPLIED WARRANTIES OF MERCHANTABILITY AND FITNESS FOR A PARTICULAR
PURPOSE ARE DISCLAIMED. IN NO EVENT SHALL THE COPYRIGHT HOLDER OR CONTRIBUTORS BE LIABLE FOR ANY DIRECT, IN-
DIRECT, INCIDENTAL, SPECIAL, EXEMPLARY, OR CONSEQUENTIAL DAMAGES (INCLUDING, BUT NOT LIMITED TO, PROCUREMENT
OF SUBSTITUTE GOODS OR SERVICES; LOSS OF USE, DATA, OR PROFITS; OR BUSINESS INTERRUPTION) HOWEVER CAUSED AND
ON ANY THEORY OF LIABILITY, WHETHER IN CONTRACT, STRICT LIABILITY, OR TORT (INCLUDING NEGLIGENCE OR OTHERWISE)
ARISING IN ANY WAY OUT OF THE USE OF THIS SOFTWARE, EVEN IF ADVISED OF THE POSSIBILITY OF SUCH DAMAGE.
-->
<robot name="husky">
    <material name="dark_grey">
        <color rgba="0.2 0.2 0.2 1.0" />
    </material>
    <material name="medium_grey">
        <color rgba="0.6 0.6 0.6 1.0" />
    </material>
    <material name="light_grey">
        <color rgba="0.8 0.8 0.8 1.0" />
    </material>
    <material name="yellow">
        <color rgba="0.8 0.8 0.0 1.0" />
    </material>
    <material name="black">
        <color rgba="0.15 0.15 0.15 1.0" />
    </material>
    <material name="white">
        <color rgba="1.0 1.0 1.0 1.0" />
    </material>
    <material name="red">
        <color rgba="1.0 0.0 0.0 1.0" />
    </material>
    <!-- Base link is the center of the robot's bottom plate -->
    <link name="base_link">
        <visual>
            <origin rpy="0 0 0" xyz="0 0 0" />
            <geometry>
                <mesh filename="package://husky_description/meshes/base_link.dae" />
            </geometry>
        </visual>
        <collision>
            <origin rpy="0 0 0" xyz="0.0 0 0.061875" />
            <geometry>
                <box size="0.9874 0.5709 0.12375" />
            </geometry>
        </collision>
        <collision>
            <origin rpy="0 0 0" xyz="0 0 0.17562499999999998" />
            <geometry>
                <box size="0.7899200000000001 0.5709 0.10375" />
            </geometry>
        </collision>
        <inertial>
            <mass value="0.1" />
            <origin xyz="0 0 0" rpy="0 0 0" />
            <inertia ixx="0.03" iyy="0.03" izz="0.03" ixy="0.0" ixz="0.0" iyz="0.0" />
        </inertial>
    </link>
    <!-- Base footprint is on the ground under the robot -->
    <link name="base_footprint" />
    <joint name="base_footprint_joint" type="fixed">
        <origin rpy="0 0 0" xyz="0 0 -0.13228" />
        <parent link="base_link" />
        <child link="base_footprint" />
    </joint>
    <!-- Inertial link stores the robot's inertial information -->
    <link name="inertial_link">
        <inertial>
            <mass value="46.034" />
            <origin xyz="-0.00065 -0.085 0.062" />
            <inertia ixx="0.6022" ixy="-0.02364" ixz="-0.1197" iyy="1.7386" iyz="-0.001544" izz="2.0296" />
        </inertial>
    </link>
    <joint name="inertial_joint" type="fixed">
        <origin rpy="0 0 0" xyz="0 0 0" />
        <parent link="base_link" />
        <child link="inertial_link" />
    </joint>
    <!-- IMU Link is the standard mounting position for the UM6 IMU.-->
    <!-- Can be modified with environment variables in /etc/ros/setup.bash -->
    <link name="imu_link" />
    <joint name="imu_joint" type="fixed">
        <origin rpy="0 -1.5708 3.1416" xyz="0.19 0 0.149" />
        <parent link="base_link" />
        <child link="imu_link" />
    </joint>
    <gazebo reference="imu_link">
        <plugin name="gazebo_ros_control">
            <robotNamespace>/</robotNamespace>
        </plugin>
    </gazebo>
    <link name="front_left_wheel_link">
        <inertial>
            <mass value="2.637" />
            <origin xyz="0 0 0" rpy="0 0 0" />
            <inertia ixx="0.02467" ixy="0" ixz="0" iyy="0.04411" iyz="0" izz="0.02467" />
        </inertial>
        <visual>
            <origin rpy="0 0 0" xyz="0 0 0" />
            <geometry>
                <mesh filename="package://husky_description/meshes/wheel.dae" />
            </geometry>
        </visual>
        <collision>
            <origin rpy="1.570795 0 0" xyz="0 0 0" />
            <geometry>
                <cylinder length="0.1143" radius="0.1651" />
            </geometry>
        </collision>
    </link>
    <gazebo reference="front_left_wheel_link">
        <mu1 value="1.0" />
        <mu2 value="1.0" />
        <kp value="10000000.0" />
        <kd value="1.0" />
        <fdir1 value="1 0 0" />
    </gazebo>
    <joint name="front_left_wheel" type="continuous">
        <parent link="base_link" />
        <child link="front_left_wheel_link" />
        <origin rpy="0 0 0" xyz="0.256 0.2854 0.03282" />
        <axis rpy="0 0 0" xyz="0 1 0" />
    </joint>
    <transmission name="front_left_wheel_trans" type="SimpleTransmission">
        <type>transmission_interface/SimpleTransmission</type>
        <actuator name="front_left_wheel_motor">
            <mechanicalReduction>1</mechanicalReduction>
            <hardwareInterface>hardware_interface/EffortJointInterface</hardwareInterface>
        </actuator>
        <joint name="front_left_wheel">
            <hardwareInterface>hardware_interface/VelocityJointInterface</hardwareInterface>
        </joint>
    </transmission>
    <link name="front_right_wheel_link">
        <inertial>
            <mass value="2.637" />
            <origin xyz="0 0 0" rpy="0 0 0" />
            <inertia ixx="0.02467" ixy="0" ixz="0" iyy="0.04411" iyz="0" izz="0.02467" />
        </inertial>
        <visual>
            <origin rpy="0 0 0" xyz="0 0 0" />
            <geometry>
                <mesh filename="package://husky_description/meshes/wheel.dae" />
            </geometry>
        </visual>
        <collision>
            <origin rpy="1.570795 0 0" xyz="0 0 0" />
            <geometry>
                <cylinder length="0.1143" radius="0.1651" />
            </geometry>
        </collision>
    </link>
    <gazebo reference="front_right_wheel_link">
        <mu1 value="1.0" />
        <mu2 value="1.0" />
        <kp value="10000000.0" />
        <kd value="1.0" />
        <fdir1 value="1 0 0" />
    </gazebo>
    <joint name="front_right_wheel" type="continuous">
        <parent link="base_link" />
        <child link="front_right_wheel_link" />
        <origin rpy="0 0 0" xyz="0.256 -0.2854 0.03282" />
        <axis rpy="0 0 0" xyz="0 1 0" />
    </joint>
    <transmission name="front_right_wheel_trans" type="SimpleTransmission">
        <type>transmission_interface/SimpleTransmission</type>
        <actuator name="front_right_wheel_motor">
            <mechanicalReduction>1</mechanicalReduction>
            <hardwareInterface>hardware_interface/EffortJointInterface</hardwareInterface>
        </actuator>
        <joint name="front_right_wheel">
            <hardwareInterface>hardware_interface/VelocityJointInterface</hardwareInterface>
        </joint>
    </transmission>
    <link name="rear_left_wheel_link">
        <inertial>
            <mass value="2.637" />
            <origin xyz="0 0 0" rpy="0 0 0" />
            <inertia ixx="0.02467" ixy="0" ixz="0" iyy="0.04411" iyz="0" izz="0.02467" />
        </inertial>
        <visual>
            <origin rpy="0 0 0" xyz="0 0 0" />
            <geometry>
                <mesh filename="package://husky_description/meshes/wheel.dae" />
            </geometry>
        </visual>
        <collision>
            <origin rpy="1.570795 0 0" xyz="0 0 0" />
            <geometry>
                <cylinder length="0.1143" radius="0.1651" />
            </geometry>
        </collision>
    </link>
    <gazebo reference="rear_left_wheel_link">
        <mu1 value="1.0" />
        <mu2 value="1.0" />
        <kp value="10000000.0" />
        <kd value="1.0" />
        <fdir1 value="1 0 0" />
    </gazebo>
    <joint name="rear_left_wheel" type="continuous">
        <parent link="base_link" />
        <child link="rear_left_wheel_link" />
        <origin rpy="0 0 0" xyz="-0.256 0.2854 0.03282" />
        <axis rpy="0 0 0" xyz="0 1 0" />
    </joint>
    <transmission name="rear_left_wheel_trans" type="SimpleTransmission">
        <type>transmission_interface/SimpleTransmission</type>
        <actuator name="rear_left_wheel_motor">
            <mechanicalReduction>1</mechanicalReduction>
            <hardwareInterface>hardware_interface/EffortJointInterface</hardwareInterface>
        </actuator>
        <joint name="rear_left_wheel">
            <hardwareInterface>hardware_interface/VelocityJointInterface</hardwareInterface>
        </joint>
    </transmission>
    <link name="rear_right_wheel_link">
        <inertial>
            <mass value="2.637" />
            <origin xyz="0 0 0" rpy="0 0 0" />
            <inertia ixx="0.02467" ixy="0" ixz="0" iyy="0.04411" iyz="0" izz="0.02467" />
        </inertial>
        <visual>
            <origin rpy="0 0 0" xyz="0 0 0" />
            <geometry>
                <mesh filename="package://husky_description/meshes/wheel.dae" />
            </geometry>
        </visual>
        <collision>
            <origin rpy="1.570795 0 0" xyz="0 0 0" />
            <geometry>
                <cylinder length="0.1143" radius="0.1651" />
            </geometry>
        </collision>
    </link>
    <gazebo reference="rear_right_wheel_link">
        <mu1 value="1.0" />
        <mu2 value="1.0" />
        <kp value="10000000.0" />
        <kd value="1.0" />
        <fdir1 value="1 0 0" />
    </gazebo>
    <joint name="rear_right_wheel" type="continuous">
        <parent link="base_link" />
        <child link="rear_right_wheel_link" />
        <origin rpy="0 0 0" xyz="-0.256 -0.2854 0.03282" />
        <axis rpy="0 0 0" xyz="0 1 0" />
    </joint>
    <transmission name="rear_right_wheel_trans" type="SimpleTransmission">
        <type>transmission_interface/SimpleTransmission</type>
        <actuator name="rear_right_wheel_motor">
            <mechanicalReduction>1</mechanicalReduction>
            <hardwareInterface>hardware_interface/EffortJointInterface</hardwareInterface>
        </actuator>
        <joint name="rear_right_wheel">
            <hardwareInterface>hardware_interface/VelocityJointInterface</hardwareInterface>
        </joint>
    </transmission>
    <!--
      CHASSIS: Spawn and attach default chassis.
               Currently, no customization available.
    -->
    <!-- Spawn Husky chassis -->
    <link name="top_chassis_link">
        <visual>
            <origin rpy="0 0 0" xyz="0 0 0" />
            <geometry>
                <mesh filename="package://husky_description/meshes/top_chassis.dae" />
            </geometry>
        </visual>
    </link>
    <!-- Attach chassis to the robot -->
    <joint name="top_chassis_joint" type="fixed">
        <parent link="base_link" />
        <child link="top_chassis_link" />
    </joint>
    <link name="front_bumper_link">
        <visual>
            <geometry>
                <mesh filename="package://husky_description/meshes/bumper.dae" />
            </geometry>
        </visual>
    </link>
    <!-- Attach front bumper -->
    <joint name="front_bumper" type="fixed">
        <origin rpy="0 0 0" xyz="0.48 0 0.091" />
        <parent link="base_link" />
        <child link="front_bumper_link" />
    </joint>
    <link name="rear_bumper_link">
        <visual>
            <geometry>
                <mesh filename="package://husky_description/meshes/bumper.dae" />
            </geometry>
        </visual>
    </link>
    <!-- Attach rear bumper -->
    <joint name="rear_bumper" type="fixed">
        <origin rpy="0 0 3.14159" xyz="-0.48 0 0.091" />
        <parent link="base_link" />
        <child link="rear_bumper_link" />
    </joint>
    <!-- Spawn user rails -->
    <link name="user_rail_link">
        <visual>
            <geometry>
                <mesh filename="package://husky_description/meshes/user_rail.dae" />
            </geometry>
        </visual>
    </link>
    <!-- Attach user rails to base link -->
    <joint name="user_rail" type="fixed">
        <origin rpy="0 0 0" xyz="0.272 0 0.245" />
        <parent link="base_link" />
        <child link="user_rail_link" />
    </joint>
    <!-- Spawn default top plate -->
    <link name="top_plate_link">
        <visual>
            <origin rpy="0 0 0" xyz="0 0 0" />
            <geometry>
                <mesh filename="package://husky_description/meshes/top_plate.dae" />
            </geometry>
        </visual>
        <collision>
            <origin rpy="0 0 0" xyz="0 0 0" />
            <geometry>
                <mesh filename="package://husky_description/meshes/top_plate.stl" />
            </geometry>
        </collision>
        <inertial>
            <mass value="0.1" />
            <origin xyz="0 0 0" rpy="0 0 0" />
            <inertia ixx="0.03" iyy="0.03" izz="0.03" ixy="0.0" ixz="0.0" iyz="0.0" />
        </inertial>
    </link>
    <!-- Attach default top plate -->
    <joint name="top_plate_joint" type="fixed">
        <parent link="base_link" />
        <child link="top_plate_link" />
        <origin rpy="0 0 0" xyz="0.0812 0 0.245" />
    </joint>
    <!-- Default top plate front link -->
    <link name="top_plate_front_link" />
    <joint name="top_plate_front_joint" type="fixed">
        <parent link="top_plate_link" />
        <child link="top_plate_front_link" />
        <origin rpy="0 0 0" xyz="0.36367 0 0.00639" />
    </joint>
    <!-- Default top plate rear link-->
    <link name="top_plate_rear_link" />
    <joint name="top_plate_rear_joint" type="fixed">
        <parent link="top_plate_link" />
        <child link="top_plate_rear_link" />
        <origin rpy="0 0 0" xyz="-0.36633 0 0.00639" />
    </joint>
    <gazebo>
        <plugin filename="libgazebo_ros_control.so" name="gazebo_ros_control">
            <robotNamespace>/</robotNamespace>
            <legacyModeNS>true</legacyModeNS>
        </plugin>
    </gazebo>
    <gazebo>
        <plugin filename="libhector_gazebo_ros_imu.so" name="imu_controller">
            <robotNamespace>/</robotNamespace>
            <updateRate>50.0</updateRate>
            <bodyName>base_link</bodyName>
            <topicName>imu/data</topicName>
            <accelDrift>0.005 0.005 0.005</accelDrift>
            <accelGaussianNoise>0.005 0.005 0.005</accelGaussianNoise>
            <rateDrift>0.005 0.005 0.005</rateDrift>
            <rateGaussianNoise>0.005 0.005 0.005</rateGaussianNoise>
            <headingDrift>0.005</headingDrift>
            <headingGaussianNoise>0.005</headingGaussianNoise>
        </plugin>
    </gazebo>
    <gazebo>
        <plugin filename="libhector_gazebo_ros_gps.so" name="gps_controller">
            <robotNamespace>/</robotNamespace>
            <updateRate>40</updateRate>
            <bodyName>base_link</bodyName>
            <frameId>base_link</frameId>
            <topicName>navsat/fix</topicName>
            <velocityTopicName>navsat/vel</velocityTopicName>
            <referenceLatitude>49.9</referenceLatitude>
            <referenceLongitude>8.9</referenceLongitude>
            <referenceHeading>0</referenceHeading>
            <referenceAltitude>0</referenceAltitude>
            <drift>0.0001 0.0001 0.0001</drift>
        </plugin>
    </gazebo>
    <!--
  Author: Jason Peng <jason@ufactory.cc>
  Contributers:
-->
    <gazebo>
        <plugin filename="libgazebo_ros_control.so" name="gazebo_ros_control">
            <robotNamespace>/xarm</robotNamespace>
            <!-- <controlPeriod>0.0001</controlPeriod> -->
            <robotSimType>gazebo_ros_control/DefaultRobotHWSim</robotSimType>
            <legacyModeNS>true</legacyModeNS>
            <!-- <preserveWorldVelocity>true</preserveWorldVelocity> -->
        </plugin>
    </gazebo>
    <joint name="world_joint" type="fixed">
        <parent link="xarm_connector_link" />
        <child link="link_base" />
        <origin rpy="0 0 0" xyz="0 0 0" />
    </joint>
    <material name="Black">
        <color rgba="0.0 0.0 0.0 1.0" />
    </material>
    <material name="Red">
        <color rgba="0.8 0.0 0.0 1.0" />
    </material>
    <material name="White">
        <color rgba="1.0 1.0 1.0 1.0" />
    </material>
    <material name="Silver">
        <color rgba="0.753 0.753 0.753 1.0" />
    </material>
    <link name="link_base">
        <visual>
            <geometry>
                <mesh filename="package://xarm_description/meshes/xarm6/visual/base.stl" />
            </geometry>
            <origin rpy="0 0 0" xyz="0 0 0" />
            <material name="White" />
        </visual>
        <collision>
            <geometry>
                <mesh filename="package://xarm_description/meshes/xarm6/visual/base.stl" />
            </geometry>
            <origin rpy="0 0 0" xyz="0 0 0" />
        </collision>
        <inertial>
            <origin rpy="0 0 0" xyz="0.0 0.0 0.09103" />
            <mass value="2.7" />
            <inertia ixx="0.00494875" ixy="-3.5E-06" ixz="1.25E-05" iyy="0.00494174" iyz="1.67E-06" izz="0.002219" />
        </inertial>
    </link>
    <link name="link1">
        <visual>
            <geometry>
                <mesh filename="package://xarm_description/meshes/xarm6/visual/link1.stl" />
            </geometry>
            <origin rpy="0 0 0" xyz="0 0 0" />
            <material name="White" />
        </visual>
        <collision>
            <geometry>
                <mesh filename="package://xarm_description/meshes/xarm6/visual/link1.stl" />
            </geometry>
            <origin rpy="0 0 0" xyz="0 0 0" />
        </collision>
        <inertial>
            <origin rpy="0 0 0" xyz="-0.002 0.02692 -0.01332" />
            <mass value="2.16" />
            <inertia ixx="0.00539427" ixy="1.095E-05" ixz="1.635E-06" iyy="0.0048979" iyz="0.000793" izz="0.00311573" />
        </inertial>
    </link>
    <joint name="joint1" type="revolute">
        <parent link="link_base" />
        <child link="link1" />
        <origin rpy="0 0 0" xyz="0 0 0.267" />
        <axis xyz="0 0 1" />
        <limit effort="50.0" lower="-6.283185307179586" upper="6.283185307179586" velocity="3.14" />
        <dynamics damping="1.0" friction="1.0" />
    </joint>
    <link name="link2">
        <visual>
            <geometry>
                <mesh filename="package://xarm_description/meshes/xarm6/visual/link2.stl" />
            </geometry>
            <origin rpy="0 0 0" xyz="0 0 0" />
            <material name="White" />
        </visual>
        <collision>
            <geometry>
                <mesh filename="package://xarm_description/meshes/xarm6/visual/link2.stl" />
            </geometry>
            <origin rpy="0 0 0" xyz="0 0 0" />
        </collision>
        <inertial>
            <origin rpy="0 0 0" xyz="0.03531 -0.21398 0.03386" />
            <mass value="1.71" />
            <inertia ixx="0.0248674" ixy="-0.00430651" ixz="-0.00067797" iyy="0.00485548" iyz="0.00457245" izz="0.02387827" />
        </inertial>
    </link>
    <joint name="joint2" type="revolute">
        <parent link="link1" />
        <child link="link2" />
        <origin rpy="-1.5708 0 0" xyz="0 0 0" />
        <axis xyz="0 0 1" />
        <limit effort="50.0" lower="-2.059" upper="2.0944" velocity="3.14" />
        <dynamics damping="1.0" friction="1.0" />
    </joint>
    <link name="link3">
        <visual>
            <geometry>
                <mesh filename="package://xarm_description/meshes/xarm6/visual/link3.stl" />
            </geometry>
            <origin rpy="0 0 0" xyz="0 0 0" />
            <material name="White" />
        </visual>
        <collision>
            <geometry>
                <mesh filename="package://xarm_description/meshes/xarm6/visual/link3.stl" />
            </geometry>
            <origin rpy="0 0 0" xyz="0 0 0" />
        </collision>
        <inertial>
            <origin rpy="0 0 0" xyz="0.06781 0.10749 0.01457" />
            <mass value="1.384" />
            <inertia ixx="0.0053694" ixy="0.0014185" ixz="-0.00092094" iyy="0.0032423" iyz="-0.00169178" izz="0.00501731" />
        </inertial>
    </link>
    <joint name="joint3" type="revolute">
        <parent link="link2" />
        <child link="link3" />
        <origin rpy="0 0 0" xyz="0.0535 -0.2845 0" />
        <axis xyz="0 0 1" />
        <limit effort="32.0" lower="-3.927" upper="0.19198" velocity="3.14" />
        <dynamics damping="1.0" friction="1.0" />
    </joint>
    <link name="link4">
        <visual>
            <geometry>
                <mesh filename="package://xarm_description/meshes/xarm6/visual/link4.stl" />
            </geometry>
            <origin rpy="0 0 0" xyz="0 0 0" />
            <material name="White" />
        </visual>
        <collision>
            <geometry>
                <mesh filename="package://xarm_description/meshes/xarm6/visual/link4.stl" />
            </geometry>
            <origin rpy="0 0 0" xyz="0 0 0" />
        </collision>
        <inertial>
            <origin rpy="0 0 0" xyz="-0.00021 0.02578 -0.02538" />
            <mass value="1.115" />
            <inertia ixx="0.00439263" ixy="5.028E-05" ixz="1.374E-05" iyy="0.0040077" iyz="0.00045338" izz="0.00110321" />
        </inertial>
    </link>
    <joint name="joint4" type="revolute">
        <parent link="link3" />
        <child link="link4" />
        <origin rpy="-1.5708 0 0" xyz="0.0775 0.3425 0" />
        <axis xyz="0 0 1" />
        <limit effort="32.0" lower="-6.283185307179586" upper="6.283185307179586" velocity="3.14" />
        <dynamics damping="1.0" friction="1.0" />
    </joint>
    <link name="link5">
        <visual>
            <geometry>
                <mesh filename="package://xarm_description/meshes/xarm6/visual/link5.stl" />
            </geometry>
            <origin rpy="0 0 0" xyz="0 0 0" />
            <material name="White" />
        </visual>
        <collision>
            <geometry>
                <mesh filename="package://xarm_description/meshes/xarm6/visual/link5.stl" />
            </geometry>
            <origin rpy="0 0 0" xyz="0 0 0" />
        </collision>
        <inertial>
            <origin rpy="0 0 0" xyz="0.05428 0.01781 0.00543" />
            <mass value="1.275" />
            <inertia ixx="0.001202758" ixy="0.000492428" ixz="-0.00039147" iyy="0.0022876" iyz="-1.235E-04" izz="0.0026866" />
        </inertial>
    </link>
    <joint name="joint5" type="revolute">
        <parent link="link4" />
        <child link="link5" />
        <origin rpy="1.5708 0 0" xyz="0 0 0" />
        <axis xyz="0 0 1" />
        <limit effort="32.0" lower="-1.69297" upper="3.141592653589793" velocity="3.14" />
        <dynamics damping="1.0" friction="1.0" />
    </joint>
    <link name="link6">
        <visual>
            <geometry>
                <mesh filename="package://xarm_description/meshes/xarm6/visual/link6.stl" />
            </geometry>
            <origin rpy="0 0 0" xyz="0 0 0" />
            <material name="Silver" />
        </visual>
        <collision>
            <geometry>
                <mesh filename="package://xarm_description/meshes/collision/end_tool.STL" />
            </geometry>
            <origin rpy="0 0 0" xyz="0 0 0" />
        </collision>
        <inertial>
            <origin rpy="0 0 0" xyz="0 0.00064 -0.00952" />
            <mass value="0.1096" />
            <inertia ixx="4.5293E-05" ixy="0" ixz="0" iyy="4.8111E-05" iyz="0" izz="7.9715E-05" />
        </inertial>
    </link>
    <joint name="joint6" type="revolute">
        <parent link="link5" />
        <child link="link6" />
        <origin rpy="-1.5708 0 0" xyz="0.076 0.097 0" />
        <axis xyz="0 0 1" />
        <limit effort="20.0" lower="-6.283185307179586" upper="6.283185307179586" velocity="3.14" />
        <dynamics damping="1.0" friction="1.0" />
    </joint>
    <link name="link_eef" />
    <joint name="joint_eef" type="fixed">
        <origin rpy="0 0 0" xyz="0 0 0" />
        <parent link="link6" />
        <child link="link_eef" />
    </joint>
    <transmission name="tran1">
        <type>transmission_interface/SimpleTransmission</type>
        <joint name="joint1">
            <hardwareInterface>hardware_interface/PositionJointInterface</hardwareInterface>
        </joint>
        <actuator name="motor1">
            <hardwareInterface>hardware_interface/PositionJointInterface</hardwareInterface>
            <mechanicalReduction>100</mechanicalReduction>
        </actuator>
    </transmission>
    <transmission name="tran2">
        <type>transmission_interface/SimpleTransmission</type>
        <joint name="joint2">
            <hardwareInterface>hardware_interface/PositionJointInterface</hardwareInterface>
        </joint>
        <actuator name="motor2">
            <hardwareInterface>hardware_interface/PositionJointInterface</hardwareInterface>
            <mechanicalReduction>100</mechanicalReduction>
        </actuator>
    </transmission>
    <transmission name="tran3">
        <type>transmission_interface/SimpleTransmission</type>
        <joint name="joint3">
            <hardwareInterface>hardware_interface/PositionJointInterface</hardwareInterface>
        </joint>
        <actuator name="motor3">
            <hardwareInterface>hardware_interface/PositionJointInterface</hardwareInterface>
            <mechanicalReduction>100</mechanicalReduction>
        </actuator>
    </transmission>
    <transmission name="tran4">
        <type>transmission_interface/SimpleTransmission</type>
        <joint name="joint4">
            <hardwareInterface>hardware_interface/PositionJointInterface</hardwareInterface>
        </joint>
        <actuator name="motor3">
            <hardwareInterface>hardware_interface/PositionJointInterface</hardwareInterface>
            <mechanicalReduction>100</mechanicalReduction>
        </actuator>
    </transmission>
    <transmission name="tran5">
        <type>transmission_interface/SimpleTransmission</type>
        <joint name="joint5">
            <hardwareInterface>hardware_interface/PositionJointInterface</hardwareInterface>
        </joint>
        <actuator name="motor5">
            <hardwareInterface>hardware_interface/PositionJointInterface</hardwareInterface>
            <mechanicalReduction>100</mechanicalReduction>
        </actuator>
    </transmission>
    <transmission name="tran6">
        <type>transmission_interface/SimpleTransmission</type>
        <joint name="joint6">
            <hardwareInterface>hardware_interface/PositionJointInterface</hardwareInterface>
        </joint>
        <actuator name="motor6">
            <hardwareInterface>hardware_interface/PositionJointInterface</hardwareInterface>
            <mechanicalReduction>100</mechanicalReduction>
        </actuator>
    </transmission>
    <gazebo reference="link_base">
        <selfCollide>true</selfCollide>
    </gazebo>
    <gazebo reference="link1">
        <selfCollide>true</selfCollide>
    </gazebo>
    <gazebo reference="link2">
        <selfCollide>true</selfCollide>
    </gazebo>
    <gazebo reference="link3">
        <selfCollide>true</selfCollide>
    </gazebo>
    <gazebo reference="link4">
        <selfCollide>true</selfCollide>
    </gazebo>
    <gazebo reference="link5">
        <selfCollide>true</selfCollide>
    </gazebo>
    <gazebo reference="link6">
        <selfCollide>true</selfCollide>
    </gazebo>
    <!-- Phidgets IMU -->
    <link name="phidgets_imu_link" />
    <joint name="phidgets_imu_joint" type="fixed">
        <parent link="base_link" />
        <child link="phidgets_imu_link" />
        <origin rpy="0 0 0" xyz="0.19 0 0.149" />
    </joint>
    <!-- xArm6 -->
    <link name="xarm_connector_link" />
    <joint name="xarm_connector_joint" type="fixed">
        <parent link="base_link" />
        <child link="xarm_connector_link" />
        <origin rpy="0 0 0" xyz="0.35 0 0.25" />
    </joint>
    <link name="robotiq_arg2f_base_link">
        <inertial>
            <origin rpy="0 0 0" xyz="8.625E-08 -4.6583E-06 0.03145" />
            <mass value="0.22652" />
            <inertia ixx="0.00020005" ixy="-4.2442E-10" ixz="-2.9069E-10" iyy="0.00017832" iyz="-3.4402E-08" izz="0.00013478" />
        </inertial>
        <visual>
            <origin rpy="0 0 0" xyz="0 0 0" />
            <geometry>
                <mesh filename="package://robotiq_2f_140_gripper_visualization/meshes/visual/robotiq_arg2f_base_link.stl" />
            </geometry>
            <material name="">
                <color rgba="0.1 0.1 0.1 1" />
            </material>
        </visual>
        <collision>
            <origin rpy="0 0 0" xyz="0 0 0" />
            <geometry>
                <mesh filename="package://robotiq_2f_140_gripper_visualization/meshes/collision/robotiq_arg2f_base_link.stl" />
            </geometry>
        </collision>
    </link>
    <gazebo reference="robotiq_arg2f_base_link">
        <material>Gazebo/FlatBlack</material>
    </gazebo>
    <joint name="left_finger_joint" type="revolute">
        <origin rpy="2.2957963267948966 0 0" xyz="0 -0.030601 0.054905" />
        <parent link="robotiq_arg2f_base_link" />
        <child link="left_outer_knuckle" />
        <axis xyz="-1 0 0" />
        <limit effort="1000" lower="0" upper="0.7" velocity="2.0" />
    </joint>
    <joint name="left_outer_finger_joint" type="fixed">
        <origin rpy="0 0 0" xyz="0 0.01821998610742 0.0260018192872234" />
        <parent link="left_outer_knuckle" />
        <child link="left_outer_finger" />
        <axis xyz="1 0 0" />
    </joint>
    <joint name="left_inner_knuckle_joint" type="revolute">
        <origin rpy="2.2957963267948966 0 0.0" xyz="0 -0.0127 0.06142" />
        <parent link="robotiq_arg2f_base_link" />
        <child link="left_inner_knuckle" />
        <axis xyz="1 0 0" />
        <limit effort="1000" lower="-0.8757" upper="0.8757" velocity="2.0" />
        <mimic joint="left_finger_joint" multiplier="-1" offset="0" />
    </joint>
    <joint name="left_inner_finger_joint" type="revolute">
        <origin rpy="-0.725 0 0" xyz="0 0.0817554015893473 -0.0282203446692936" />
        <parent link="left_outer_finger" />
        <child link="left_inner_finger" />
        <axis xyz="1 0 0" />
        <limit effort="1000" lower="-0.8757" upper="0.8757" velocity="2.0" />
        <mimic joint="left_finger_joint" multiplier="1" offset="0" />
    </joint>
    <joint name="left_inner_finger_pad_joint" type="fixed">
        <origin rpy="0 0 0" xyz="0 0.0457554015893473 -0.0272203446692936" />
        <parent link="left_inner_finger" />
        <child link="left_inner_finger_pad" />
        <axis xyz="0 0 1" />
    </joint>
    <link name="left_outer_knuckle">
        <inertial>
            <origin rpy="0 0 0" xyz="-0.000200000000003065 0.0199435877845359 0.0292245259211331" />
            <mass value="0.00853198276973456" />
            <inertia ixx="2.89328108496468E-06" ixy="-1.57935047237397E-19" ixz="-1.93980378593255E-19" iyy="1.86719750325683E-06" iyz="-1.21858577871576E-06" izz="1.21905238907251E-06" />
        </inertial>
        <visual>
            <origin rpy="0 0 0" xyz="0 0 0" />
            <geometry>
                <mesh filename="package://robotiq_2f_140_gripper_visualization/meshes/visual/robotiq_arg2f_140_outer_knuckle.stl" />
            </geometry>
            <material name="">
                <color rgba="0.792156862745098 0.819607843137255 0.933333333333333 1" />
            </material>
        </visual>
        <collision>
            <origin rpy="0 0 0" xyz="0 0 0" />
            <geometry>
                <mesh filename="package://robotiq_2f_140_gripper_visualization/meshes/collision/robotiq_arg2f_140_outer_knuckle.stl" />
            </geometry>
        </collision>
    </link>
    <gazebo reference="left_outer_knuckle">
        <material>Gazebo/DarkGrey</material>
    </gazebo>
    <link name="left_outer_finger">
        <inertial>
            <origin rpy="0 0 0" xyz="0.00030115855001899 0.0373907951953854 -0.0208027427000385" />
            <mass value="0.022614240507152" />
            <inertia ixx="1.52518312458174E-05" ixy="9.76583423954399E-10" ixz="-5.43838577022588E-10" iyy="6.17694243867776E-06" iyz="6.78636130740228E-06" izz="1.16494917907219E-05" />
        </inertial>
        <visual>
            <origin rpy="0 0 0" xyz="0 0 0" />
            <geometry>
                <mesh filename="package://robotiq_2f_140_gripper_visualization/meshes/visual/robotiq_arg2f_140_outer_finger.stl" />
            </geometry>
            <material name="">
                <color rgba="0.1 0.1 0.1 1" />
            </material>
        </visual>
        <collision>
            <origin rpy="0 0 0" xyz="0 0 0" />
            <geometry>
                <mesh filename="package://robotiq_2f_140_gripper_visualization/meshes/collision/robotiq_arg2f_140_outer_finger.stl" />
            </geometry>
        </collision>
    </link>
    <gazebo reference="left_outer_finger">
        <material>Gazebo/FlatBlack</material>
    </gazebo>
    <link name="left_inner_finger">
        <inertial>
            <origin rpy="0 0 0" xyz="0.000299999999999317 0.0160078233491243 -0.0136945669206257" />
            <mass value="0.0104003125914103" />
            <inertia ixx="2.71909453810972E-06" ixy="1.35402465472579E-21" ixz="-7.1817349065269E-22" iyy="7.69100314106116E-07" iyz="6.74715432769696E-07" izz="2.30315190420171E-06" />
        </inertial>
        <visual>
            <origin rpy="0 0 0" xyz="0 0 0" />
            <geometry>
                <mesh filename="package://robotiq_2f_140_gripper_visualization/meshes/visual/robotiq_arg2f_140_inner_finger.stl" />
            </geometry>
            <material name="">
                <color rgba="0.1 0.1 0.1 1" />
            </material>
        </visual>
        <collision>
            <origin rpy="0 0 0" xyz="0 0 0" />
            <geometry>
                <mesh filename="package://robotiq_2f_140_gripper_visualization/meshes/collision/robotiq_arg2f_140_inner_finger.stl" />
            </geometry>
        </collision>
    </link>
    <gazebo reference="left_inner_finger">
        <material>Gazebo/DarkGrey</material>
    </gazebo>
    <link name="left_inner_finger_pad">
        <visual>
            <origin rpy="0 0 0" xyz="0 0 0" />
            <geometry>
                <box size="0.027 0.065 0.0075" />
            </geometry>
            <material name="">
                <color rgba="0.9 0.9 0.9 1" />
            </material>
        </visual>
        <collision>
            <origin rpy="0 0 0" xyz="0 0 0" />
            <geometry>
                <box size="0.03 0.07 0.0075" />
            </geometry>
            <material name="">
                <color rgba="0.9 0.0 0.0 1" />
            </material>
            <surface>
                <friction>
                    <ode>
                        <mu>0.7</mu>
                        <mu2>0.7</mu2>
                    </ode>
                </friction>
            </surface>
        </collision>
        <inertial>
            <mass value="0.1" />
            <origin xyz="0 0 0" rpy="0 0 0" />
            <inertia ixx="0.03" iyy="0.03" izz="0.03" ixy="0.0" ixz="0.0" iyz="0.0" />
        </inertial>
    </link>
    <gazebo reference="left_inner_finger_pad">
        <collision name="left_inner_finger_pad">
            <surface>
                <friction>
                    <torsional>
                        <coefficient>10.0</coefficient>
                        <use_patch_radius>true</use_patch_radius>
                        <patch_radius>0.05</patch_radius>
                    </torsional>
                </friction>
                <contact>
                    <poissons_ratio>0.5</poissons_ratio>
                    <elastic_modulus>1e8</elastic_modulus>
                </contact>
            </surface>
        </collision>
        <mu1>10</mu1>
        <mu2>10</mu2>
        <maxVel>1</maxVel>
        <kp>1000000.0</kp>
        <kd>100.0</kd>
        <fdir1>0 0 1</fdir1>
        <minDepth>0.0</minDepth>
        <maxContacts>100</maxContacts>
        <material>Gazebo/DarkGrey</material>
    </gazebo>
    <link name="left_inner_knuckle">
        <inertial>
            <origin rpy="0 0 0" xyz="0.000123011831763771 0.0507850843201817 0.00103968640075166" />
            <mass value="0.0271177346495152" />
            <inertia ixx="2.61910379223783E-05" ixy="-2.43616858946494E-07" ixz="-6.37789906117123E-09" iyy="2.8270243746167E-06" iyz="-5.37200748039765E-07" izz="2.83695868220296E-05" />
        </inertial>
        <visual>
            <origin rpy="0 0 0" xyz="0 0 0" />
            <geometry>
                <mesh filename="package://robotiq_2f_140_gripper_visualization/meshes/visual/robotiq_arg2f_140_inner_knuckle.stl" />
            </geometry>
            <material name="">
                <color rgba="0.1 0.1 0.1 1" />
            </material>
        </visual>
        <collision>
            <origin rpy="0 0 0" xyz="0 0 0" />
            <geometry>
                <mesh filename="package://robotiq_2f_140_gripper_visualization/meshes/collision/robotiq_arg2f_140_inner_knuckle.stl" />
            </geometry>
        </collision>
    </link>
    <gazebo reference="left_inner_knuckle">
        <material>Gazebo/FlatBlack</material>
    </gazebo>
    <joint name="right_finger_joint" type="revolute">
        <origin rpy="2.2957963267948966 0 3.141592653589793" xyz="0 0.030601 0.054905" />
        <parent link="robotiq_arg2f_base_link" />
        <child link="right_outer_knuckle" />
        <axis xyz="-1 0 0" />
        <limit effort="1000" lower="0" upper="0.7" velocity="2.0" />
    </joint>
    <joint name="right_outer_finger_joint" type="fixed">
        <origin rpy="0 0 0" xyz="0 0.01821998610742 0.0260018192872234" />
        <parent link="right_outer_knuckle" />
        <child link="right_outer_finger" />
        <axis xyz="1 0 0" />
    </joint>
    <joint name="right_inner_knuckle_joint" type="revolute">
        <origin rpy="2.2957963267948966 0 -3.141592653589793" xyz="0 0.0127 0.06142" />
        <parent link="robotiq_arg2f_base_link" />
        <child link="right_inner_knuckle" />
        <axis xyz="1 0 0" />
        <limit effort="1000" lower="-0.8757" upper="0.8757" velocity="2.0" />
        <mimic joint="right_finger_joint" multiplier="-1" offset="0" />
    </joint>
    <joint name="right_inner_finger_joint" type="revolute">
        <origin rpy="-0.725 0 0" xyz="0 0.0817554015893473 -0.0282203446692936" />
        <parent link="right_outer_finger" />
        <child link="right_inner_finger" />
        <axis xyz="1 0 0" />
        <limit effort="1000" lower="-0.8757" upper="0.8757" velocity="2.0" />
        <mimic joint="right_finger_joint" multiplier="1" offset="0" />
    </joint>
    <joint name="right_inner_finger_pad_joint" type="fixed">
        <origin rpy="0 0 0" xyz="0 0.0457554015893473 -0.0272203446692936" />
        <parent link="right_inner_finger" />
        <child link="right_inner_finger_pad" />
        <axis xyz="0 0 1" />
    </joint>
    <link name="right_outer_knuckle">
        <inertial>
            <origin rpy="0 0 0" xyz="-0.000200000000003065 0.0199435877845359 0.0292245259211331" />
            <mass value="0.00853198276973456" />
            <inertia ixx="2.89328108496468E-06" ixy="-1.57935047237397E-19" ixz="-1.93980378593255E-19" iyy="1.86719750325683E-06" iyz="-1.21858577871576E-06" izz="1.21905238907251E-06" />
        </inertial>
        <visual>
            <origin rpy="0 0 0" xyz="0 0 0" />
            <geometry>
                <mesh filename="package://robotiq_2f_140_gripper_visualization/meshes/visual/robotiq_arg2f_140_outer_knuckle.stl" />
            </geometry>
            <material name="">
                <color rgba="0.792156862745098 0.819607843137255 0.933333333333333 1" />
            </material>
        </visual>
        <collision>
            <origin rpy="0 0 0" xyz="0 0 0" />
            <geometry>
                <mesh filename="package://robotiq_2f_140_gripper_visualization/meshes/collision/robotiq_arg2f_140_outer_knuckle.stl" />
            </geometry>
        </collision>
    </link>
    <gazebo reference="right_outer_knuckle">
        <material>Gazebo/DarkGrey</material>
    </gazebo>
    <link name="right_outer_finger">
        <inertial>
            <origin rpy="0 0 0" xyz="0.00030115855001899 0.0373907951953854 -0.0208027427000385" />
            <mass value="0.022614240507152" />
            <inertia ixx="1.52518312458174E-05" ixy="9.76583423954399E-10" ixz="-5.43838577022588E-10" iyy="6.17694243867776E-06" iyz="6.78636130740228E-06" izz="1.16494917907219E-05" />
        </inertial>
        <visual>
            <origin rpy="0 0 0" xyz="0 0 0" />
            <geometry>
                <mesh filename="package://robotiq_2f_140_gripper_visualization/meshes/visual/robotiq_arg2f_140_outer_finger.stl" />
            </geometry>
            <material name="">
                <color rgba="0.1 0.1 0.1 1" />
            </material>
        </visual>
        <collision>
            <origin rpy="0 0 0" xyz="0 0 0" />
            <geometry>
                <mesh filename="package://robotiq_2f_140_gripper_visualization/meshes/collision/robotiq_arg2f_140_outer_finger.stl" />
            </geometry>
        </collision>
    </link>
    <gazebo reference="right_outer_finger">
        <material>Gazebo/FlatBlack</material>
    </gazebo>
    <link name="right_inner_finger">
        <inertial>
            <origin rpy="0 0 0" xyz="0.000299999999999317 0.0160078233491243 -0.0136945669206257" />
            <mass value="0.0104003125914103" />
            <inertia ixx="2.71909453810972E-06" ixy="1.35402465472579E-21" ixz="-7.1817349065269E-22" iyy="7.69100314106116E-07" iyz="6.74715432769696E-07" izz="2.30315190420171E-06" />
        </inertial>
        <visual>
            <origin rpy="0 0 0" xyz="0 0 0" />
            <geometry>
                <mesh filename="package://robotiq_2f_140_gripper_visualization/meshes/visual/robotiq_arg2f_140_inner_finger.stl" />
            </geometry>
            <material name="">
                <color rgba="0.1 0.1 0.1 1" />
            </material>
        </visual>
        <collision>
            <origin rpy="0 0 0" xyz="0 0 0" />
            <geometry>
                <mesh filename="package://robotiq_2f_140_gripper_visualization/meshes/collision/robotiq_arg2f_140_inner_finger.stl" />
            </geometry>
        </collision>
    </link>
    <gazebo reference="right_inner_finger">
        <material>Gazebo/DarkGrey</material>
    </gazebo>
    <link name="right_inner_finger_pad">
        <visual>
            <origin rpy="0 0 0" xyz="0 0 0" />
            <geometry>
                <box size="0.027 0.065 0.0075" />
            </geometry>
            <material name="">
                <color rgba="0.9 0.9 0.9 1" />
            </material>
        </visual>
        <collision>
            <origin rpy="0 0 0" xyz="0 0 0" />
            <geometry>
                <box size="0.03 0.07 0.0075" />
            </geometry>
            <material name="">
                <color rgba="0.9 0.0 0.0 1" />
            </material>
            <surface>
                <friction>
                    <ode>
                        <mu>0.7</mu>
                        <mu2>0.7</mu2>
                    </ode>
                </friction>
            </surface>
        </collision>
        <inertial>
            <mass value="0.1" />
            <origin xyz="0 0 0" rpy="0 0 0" />
            <inertia ixx="0.03" iyy="0.03" izz="0.03" ixy="0.0" ixz="0.0" iyz="0.0" />
        </inertial>
    </link>
    <gazebo reference="right_inner_finger_pad">
        <collision name="right_inner_finger_pad">
            <surface>
                <friction>
                    <torsional>
                        <coefficient>10.0</coefficient>
                        <use_patch_radius>true</use_patch_radius>
                        <patch_radius>0.05</patch_radius>
                    </torsional>
                </friction>
                <contact>
                    <poissons_ratio>0.5</poissons_ratio>
                    <elastic_modulus>1e8</elastic_modulus>
                </contact>
            </surface>
        </collision>
        <mu1>10</mu1>
        <mu2>10</mu2>
        <maxVel>1</maxVel>
        <kp>1000000.0</kp>
        <kd>100.0</kd>
        <fdir1>0 0 1</fdir1>
        <minDepth>0.0</minDepth>
        <maxContacts>100</maxContacts>
        <material>Gazebo/DarkGrey</material>
    </gazebo>
    <link name="right_inner_knuckle">
        <inertial>
            <origin rpy="0 0 0" xyz="0.000123011831763771 0.0507850843201817 0.00103968640075166" />
            <mass value="0.0271177346495152" />
            <inertia ixx="2.61910379223783E-05" ixy="-2.43616858946494E-07" ixz="-6.37789906117123E-09" iyy="2.8270243746167E-06" iyz="-5.37200748039765E-07" izz="2.83695868220296E-05" />
        </inertial>
        <visual>
            <origin rpy="0 0 0" xyz="0 0 0" />
            <geometry>
                <mesh filename="package://robotiq_2f_140_gripper_visualization/meshes/visual/robotiq_arg2f_140_inner_knuckle.stl" />
            </geometry>
            <material name="">
                <color rgba="0.1 0.1 0.1 1" />
            </material>
        </visual>
        <collision>
            <origin rpy="0 0 0" xyz="0 0 0" />
            <geometry>
                <mesh filename="package://robotiq_2f_140_gripper_visualization/meshes/collision/robotiq_arg2f_140_inner_knuckle.stl" />
            </geometry>
        </collision>
    </link>
    <gazebo reference="right_inner_knuckle">
        <material>Gazebo/FlatBlack</material>
    </gazebo>
    <link name="tcp" />
    <joint name="tcp_joint" type="fixed">
        <origin rpy="0 0 0" xyz="0 0 0.177" />
        <parent link="robotiq_arg2f_base_link" />
        <child link="tcp" />
    </joint>
    <joint name="gripper_arm_joint" type="fixed">
        <parent link="link_eef" />
        <child link="robotiq_arg2f_base_link" />
        <origin rpy="0 0 0" xyz="0 0 0" />
    </joint>
    <!-- Link Ouster holder base to front mount -->
    <link name="auxiliary_sensor_frame">
        <visual>
            <geometry>
                <mesh filename="package://mbs_husky_description/meshes/auxiliary_frame.dae" scale="0.01 0.01 0.01" />
            </geometry>
        </visual>
        <collision>
            <geometry>
                <mesh filename="package://mbs_husky_description/meshes/auxiliary_frame.stl" scale="0.01 0.01 0.01" />
            </geometry>
        </collision>
        <inertial>
            <mass value="0.1" />
            <origin xyz="0 0 0" rpy="0 0 0" />
            <inertia ixx="0.03" iyy="0.03" izz="0.03" ixy="0.0" ixz="0.0" iyz="0.0" />
        </inertial>
    </link>
    <joint name="ouster_holder_base_joint" type="fixed">
        <parent link="base_link" />
        <child link="auxiliary_sensor_frame" />
        <origin rpy="0 0 1.57" xyz="-0.25 0 0.25" />
    </joint>
    <!-- Link Ouster to base -->
    <link name="os_sensor">
        <visual>
            <geometry>
                <mesh filename="package://mbs_husky_description/meshes/os1_64.dae" />
            </geometry>
        </visual>
        <collision>
            <geometry>
                <mesh filename="package://mbs_husky_description/meshes/os1_64.stl" />
            </geometry>
        </collision>
        <inertial>
            <mass value="0.1" />
            <origin xyz="0 0 0" rpy="0 0 0" />
            <inertia ixx="0.03" iyy="0.03" izz="0.03" ixy="0.0" ixz="0.0" iyz="0.0" />
        </inertial>
    </link>
    <joint name="ouster_joint" type="fixed">
        <parent link="auxiliary_sensor_frame" />
        <child link="os_sensor" />
        <origin rpy="0 0 -1.57" xyz="0 0 0.46" />
    </joint>
    <!-- This file is a placeholder which is included by default from
       husky.urdf.xacro. If a robot is being customized and requires
       additional URDF, set the HUSKY_URDF_EXTRAS environment variable
       to the full path of the file you would like included. -->
    <transmission name="trans_left_finger_joint">
        <type>transmission_interface/SimpleTransmission</type>
        <joint name="left_finger_joint">
            <hardwareInterface>hardware_interface/EffortJointInterface</hardwareInterface>
        </joint>
        <actuator name="left_finger_joint_motor">
            <hardwareInterface>hardware_interface/EffortJointInterface</hardwareInterface>
            <mechanicalReduction>1</mechanicalReduction>
        </actuator>
    </transmission>
    <transmission name="trans_left_inner_knuckle_joint">
        <type>transmission_interface/SimpleTransmission</type>
        <joint name="left_inner_knuckle_joint">
            <hardwareInterface>hardware_interface/EffortJointInterface</hardwareInterface>
        </joint>
        <actuator name="left_inner_knuckle_joint_motor">
            <hardwareInterface>hardware_interface/EffortJointInterface</hardwareInterface>
            <mechanicalReduction>1</mechanicalReduction>
        </actuator>
    </transmission>
    <transmission name="trans_left_inner_finger_joint">
        <type>transmission_interface/SimpleTransmission</type>
        <joint name="left_inner_finger_joint">
            <hardwareInterface>hardware_interface/EffortJointInterface</hardwareInterface>
        </joint>
        <actuator name="left_inner_finger_joint_motor">
            <hardwareInterface>hardware_interface/EffortJointInterface</hardwareInterface>
            <mechanicalReduction>1</mechanicalReduction>
        </actuator>
    </transmission>
    <transmission name="trans_right_finger_joint">
        <type>transmission_interface/SimpleTransmission</type>
        <joint name="right_finger_joint">
            <hardwareInterface>hardware_interface/EffortJointInterface</hardwareInterface>
        </joint>
        <actuator name="right_finger_joint_motor">
            <hardwareInterface>hardware_interface/EffortJointInterface</hardwareInterface>
            <mechanicalReduction>1</mechanicalReduction>
        </actuator>
    </transmission>
    <transmission name="trans_right_inner_knuckle_joint">
        <type>transmission_interface/SimpleTransmission</type>
        <joint name="right_inner_knuckle_joint">
            <hardwareInterface>hardware_interface/EffortJointInterface</hardwareInterface>
        </joint>
        <actuator name="right_inner_knuckle_joint_motor">
            <hardwareInterface>hardware_interface/EffortJointInterface</hardwareInterface>
            <mechanicalReduction>1</mechanicalReduction>
        </actuator>
    </transmission>
    <transmission name="trans_right_inner_finger_joint">
        <type>transmission_interface/SimpleTransmission</type>
        <joint name="right_inner_finger_joint">
            <hardwareInterface>hardware_interface/EffortJointInterface</hardwareInterface>
        </joint>
        <actuator name="right_inner_finger_joint_motor">
            <hardwareInterface>hardware_interface/EffortJointInterface</hardwareInterface>
            <mechanicalReduction>1</mechanicalReduction>
        </actuator>
    </transmission>
</robot>

